Workbook
Name data: Budget!$A$1:$F$12

Sheet Dashboard
A1: MONTHLY POCKET MONEY ANALYZER & DASHBOARD
A2: Select Analysis Month: | B2: 46023 | D2: Academic Year: 2026 | G2: Currency: ₹ (INR) | J2: Dynamic Pocket Money Analytics • Real-Time Modeling
A3: TOTAL INCOME | D3: TOTAL EXPENSES | G3: NET SAVINGS | J3: SAVINGS RATE | M3: BUDGET REMAINING
A4: =SUMIFS(Transactions!$F:$F,Transactions!$C:$C,"Income",Transactions!$A:$A,">="&$B$2,Transactions!$A:$A,"<"&EDATE($B$2,1)) -> 4035 | D4: =SUMIFS(Transactions!$F:$F,Transactions!$C:$C,"Expense",Transactions!$A:$A,">="&$B$2,Transactions!$A:$A,"<"&EDATE($B$2,1)) -> 3887 | G4: =A4-D4 -> 148 | J4: =IFERROR(G4/A4,0) -> 0.036679058 | M4: =Budget!$D$13 -> 3113
A5: Monthly Pocket Money & Inflows | D5: Total Outflows across all categories | G5: Surplus / Retained Cash | J5: Target Benchmark: ≥ 20.0% | M5: Unspent Monthly Budget
A7: MONTHLY BUDGET VS ACTUAL EXPENSE BREAKDOWN | H7: BUDGET VS ACTUAL SPENDING BY CATEGORY
A8: Category | B8: Monthly Budget | C8: Actual Spending | D8: Remaining | E8: Usage (%) | F8: Status
A9: =Budget!A2 -> Food | B9: =Budget!B2 -> 1800 | C9: =Budget!C2 -> 1285 | D9: =Budget!D2 -> 515 | E9: =Budget!E2 -> 0.71388889 | F9: =Budget!F2 -> Within Budget
A10: =Budget!A3 -> Travel | B10: =Budget!B3 -> 800 | C10: =Budget!C3 -> 390 | D10: =Budget!D3 -> 410 | E10: =Budget!E3 -> 0.4875 | F10: =Budget!F3 -> Within Budget
A11: =Budget!A4 -> Stationery | B11: =Budget!B4 -> 500 | C11: =Budget!C4 -> 180 | D11: =Budget!D4 -> 320 | E11: =Budget!E4 -> 0.36 | F11: =Budget!F4 -> Within Budget
A12: =Budget!A5 -> Education | B12: =Budget!B5 -> 600 | C12: =Budget!C5 -> 255 | D12: =Budget!D5 -> 345 | E12: =Budget!E5 -> 0.425 | F12: =Budget!F5 -> Within Budget
A13: =Budget!A6 -> Entertainment | B13: =Budget!B6 -> 700 | C13: =Budget!C6 -> 568 | D13: =Budget!D6 -> 132 | E13: =Budget!E6 -> 0.81142857 | F13: =Budget!F6 -> Near Limit
A14: =Budget!A7 -> Mobile | B14: =Budget!B7 -> 300 | C14: =Budget!C7 -> 239 | D14: =Budget!D7 -> 61 | E14: =Budget!E7 -> 0.79666667 | F14: =Budget!F7 -> Within Budget
A15: =Budget!A8 -> Shopping | B15: =Budget!B8 -> 1000 | C15: =Budget!C8 -> 750 | D15: =Budget!D8 -> 250 | E15: =Budget!E8 -> 0.75 | F15: =Budget!F8 -> Within Budget
A16: =Budget!A9 -> Personal Care | B16: =Budget!B9 -> 400 | C16: =Budget!C9 -> 220 | D16: =Budget!D9 -> 180 | E16: =Budget!E9 -> 0.55 | F16: =Budget!F9 -> Within Budget
A17: =Budget!A10 -> Health | B17: =Budget!B10 -> 300 | C17: =Budget!C10 -> 0 | D17: =Budget!D10 -> 300 | E17: =Budget!E10 -> 0 | F17: =Budget!F10 -> Within Budget
A18: =Budget!A11 -> Gifts | B18: =Budget!B11 -> 300 | C18: =Budget!C11 -> 0 | D18: =Budget!D11 -> 300 | E18: =Budget!E11 -> 0 | F18: =Budget!F11 -> Within Budget
A19: =Budget!A12 -> Other | B19: =Budget!B12 -> 300 | C19: =Budget!C12 -> 0 | D19: =Budget!D12 -> 300 | E19: =Budget!E12 -> 0 | F19: =Budget!F12 -> Within Budget
A20: Total | B20: =SUM(B9:B19) -> 7000 | C20: =SUM(C9:C19) -> 3887 | D20: =B20-C20 -> 3113 | E20: =IFERROR(C20/B20,0) -> 0.55528571 | F20: =IF(C20>B20,"Over Budget",IF(C20>=B20*0.8,"Near Limit","Within Budget")) -> Within Budget
A22: 12-MONTH FINANCIAL TREND (INCOME vs EXPENSE vs SAVINGS) | H22: EXPENSE DISTRIBUTION BY CATEGORY (% SHARE)
A38: KEY MONTHLY FINANCIAL INSIGHTS & BUDGET HEALTH
A39: TOP EXPENSE CATEGORY | D39: MAX SINGLE TRANSACTION | G39: AVERAGE DAILY SPEND | J39: BUDGET ADHERENCE | M39: TOTAL TRANSACTIONS
A40: =INDEX(A9:A19, MATCH(MAX(C9:C19), C9:C19, 0)) & " (" & TEXT(MAX(C9:C19), "₹#,##0") & ")" -> Food (₹1,285) | D40: =_xlfn.MAXIFS(Transactions!$F:$F, Transactions!$C:$C, "Expense", Transactions!$A:$A, ">="&$B$2, Transactions!$A:$A, "<"&EDATE($B$2,1)) -> 450 | G40: =D4/DAY(EOMONTH($B$2,0)) -> 125.3871 | J40: =COUNTIF(F9:F19,"Within Budget") & " of 11 within limit" -> 10 of 11 within limit | M40: =COUNTIFS(Transactions!$A:$A,">="&$B$2,Transactions!$A:$A,"<"&EDATE($B$2,1)) -> 30
A42: ="Financial Health Summary: " & IF(J4>=0.2,"Outstanding savings discipline! You saved " & TEXT(J4,"0.0%") & " of your pocket money, comfortably surpassing the 20% savings target. Keep allocating surplus into your Savings Goals.", IF(J4>0,"Positive cash balance maintained (" & TEXT(J4,"0.0%") & " saved). Look into categories marked 'Near Limit' or 'Over Budget' to reduce discretionary spend and reach 20% savings.", "Warning: Expenses exceeded income this month (Deficit: " & TEXT(ABS(G4),"₹#,##0") & "). Immediate spending reductions required in high-variance categories.")) -> Financial Health Summary: Positive cash balance maintained (3.7% saved). Look into categories marked 'Near Limit' or 'Over Budget' to reduce discretionary spend and reach 20% savings.

Sheet Transactions
A1: Date | B1: Transaction ID | C1: Type | D1: Category | E1: Description | F1: Amount | G1: Payment Method | H1: Month | I1: Running Balance | J1: Budget Status
A2: 46023 | B2: TX001 | C2: Income | D2: Pocket Money | E2: Monthly allowance from parents | F2: 3000 | G2: UPI | H2: =TEXT(A2,"mmm-yyyy") -> Jan-2026 | I2: =SUMIFS($F$2:F2,$C$2:C2,"Income")-SUMIFS($F$2:F2,$C$2:C2,"Expense") -> 3000 | J2: =IF(C2="Income","-",IFERROR(VLOOKUP(D2,Budget!$A$2:$F$12,6,FALSE),"-")) -> -
A3: 46024 | B3: TX002 | C3: Expense | D3: Food | E3: Breakfast and snacks | F3: 85 | G3: UPI | H3: =TEXT(A3,"mmm-yyyy") -> Jan-2026 | I3: =SUMIFS($F$2:F3,$C$2:C3,"Income")-SUMIFS($F$2:F3,$C$2:C3,"Expense") -> 2915 | J3: =IF(C3="Income","-",IFERROR(VLOOKUP(D3,Budget!$A$2:$F$12,6,FALSE),"-")) -> Within Budget
A4: 46025 | B4: TX003 | C4: Expense | D4: Travel | E4: Bus fare | F4: 40 | G4: Cash | H4: =TEXT(A4,"mmm-yyyy") -> Jan-2026 | I4: =SUMIFS($F$2:F4,$C$2:C4,"Income")-SUMIFS($F$2:F4,$C$2:C4,"Expense") -> 2875 | J4: =IF(C4="Income","-",IFERROR(VLOOKUP(D4,Budget!$A$2:$F$12,6,FALSE),"-")) -> Within Budget
A5: 46026 | B5: TX004 | C5: Expense | D5: Food | E5: Lunch at college | F5: 120 | G5: UPI | H5: =TEXT(A5,"mmm-yyyy") -> Jan-2026 | I5: =SUMIFS($F$2:F5,$C$2:C5,"Income")-SUMIFS($F$2:F5,$C$2:C5,"Expense") -> 2755 | J5: =IF(C5="Income","-",IFERROR(VLOOKUP(D5,Budget!$A$2:$F$12,6,FALSE),"-")) -> Within Budget
A6: 46027 | B6: TX005 | C6: Expense | D6: Stationery | E6: Notebooks and pens | F6: 180 | G6: UPI | H6: =TEXT(A6,"mmm-yyyy") -> Jan-2026 | I6: =SUMIFS($F$2:F6,$C$2:C6,"Income")-SUMIFS($F$2:F6,$C$2:C6,"Expense") -> 2575 | J6: =IF(C6="Income","-",IFERROR(VLOOKUP(D6,Budget!$A$2:$F$12,6,FALSE),"-")) -> Within Budget
A7: 46028 | B7: TX006 | C7: Expense | D7: Entertainment | E7: Movie ticket | F7: 250 | G7: UPI | H7: =TEXT(A7,"mmm-yyyy") -> Jan-2026 | I7: =SUMIFS($F$2:F7,$C$2:C7,"Income")-SUMIFS($F$2:F7,$C$2:C7,"Expense") -> 2325 | J7: =IF(C7="Income","-",IFERROR(VLOOKUP(D7,Budget!$A$2:$F$12,6,FALSE),"-")) -> Near Limit
A8: 46029 | B8: TX007 | C8: Income | D8: Gift | E8: Money received from relative | F8: 500 | G8: Cash | H8: =TEXT(A8,"mmm-yyyy") -> Jan-2026 | I8: =SUMIFS($F$2:F8,$C$2:C8,"Income")-SUMIFS($F$2:F8,$C$2:C8,"Expense") -> 2825 | J8: =IF(C8="Income","-",IFERROR(VLOOKUP(D8,Budget!$A$2:$F$12,6,FALSE),"-")) -> -
A9: 46030 | B9: TX008 | C9: Expense | D9: Food | E9: Snacks with friends | F9: 110 | G9: Cash | H9: =TEXT(A9,"mmm-yyyy") -> Jan-2026 | I9: =SUMIFS($F$2:F9,$C$2:C9,"Income")-SUMIFS($F$2:F9,$C$2:C9,"Expense") -> 2715 | J9: =IF(C9="Income","-",IFERROR(VLOOKUP(D9,Budget!$A$2:$F$12,6,FALSE),"-")) -> Within Budget
A10: 46031 | B10: TX009 | C10: Expense | D10: Travel | E10: Auto fare | F10: 90 | G10: UPI | H10: =TEXT(A10,"mmm-yyyy") -> Jan-2026 | I10: =SUMIFS($F$2:F10,$C$2:C10,"Income")-SUMIFS($F$2:F10,$C$2:C10,"Expense") -> 2625 | J10: =IF(C10="Income","-",IFERROR(VLOOKUP(D10,Budget!$A$2:$F$12,6,FALSE),"-")) -> Within Budget
A11: 46032 | B11: TX010 | C11: Expense | D11: Mobile | E11: Mobile recharge | F11: 239 | G11: UPI | H11: =TEXT(A11,"mmm-yyyy") -> Jan-2026 | I11: =SUMIFS($F$2:F11,$C$2:C11,"Income")-SUMIFS($F$2:F11,$C$2:C11,"Expense") -> 2386 | J11: =IF(C11="Income","-",IFERROR(VLOOKUP(D11,Budget!$A$2:$F$12,6,FALSE),"-")) -> Within Budget
A12: 46033 | B12: TX011 | C12: Expense | D12: Food | E12: Dinner | F12: 160 | G12: UPI | H12: =TEXT(A12,"mmm-yyyy") -> Jan-2026 | I12: =SUMIFS($F$2:F12,$C$2:C12,"Income")-SUMIFS($F$2:F12,$C$2:C12,"Expense") -> 2226 | J12: =IF(C12="Income","-",IFERROR(VLOOKUP(D12,Budget!$A$2:$F$12,6,FALSE),"-")) -> Within Budget
A13: 46034 | B13: TX012 | C13: Expense | D13: Shopping | E13: T-shirt | F13: 450 | G13: UPI | H13: =TEXT(A13,"mmm-yyyy") -> Jan-2026 | I13: =SUMIFS($F$2:F13,$C$2:C13,"Income")-SUMIFS($F$2:F13,$C$2:C13,"Expense") -> 1776 | J13: =IF(C13="Income","-",IFERROR(VLOOKUP(D13,Budget!$A$2:$F$12,6,FALSE),"-")) -> Within Budget
... A60: 46090 | B60: TX059 | C60: Expense | D60: Food | E60: Snacks with friends | F60: 120 | G60: Cash | H60: =TEXT(A60,"mmm-yyyy") -> Mar-2026 | I60: =SUMIFS($F$2:F60,$C$2:C60,"Income")-SUMIFS($F$2:F60,$C$2:C60,"Expense") -> 3075 | J60: =IF(C60="Income","-",IFERROR(VLOOKUP(D60,Budget!$A$2:$F$12,6,FALSE),"-")) -> Within Budget
A61: 46091 | B61: TX060 | C61: Expense | D61: Mobile | E61: Mobile recharge | F61: 239 | G61: UPI | H61: =TEXT(A61,"mmm-yyyy") -> Mar-2026 | I61: =SUMIFS($F$2:F171,$C$2:C171,"Income")-SUMIFS($F$2:F171,$C$2:C171,"Expense") -> 1735 | J61: =IF(C61="Income","-",IFERROR(VLOOKUP(D61,Budget!$A$2:$F$12,6,FALSE),"-")) -> Within Budget
A62: 46092 | B62: TX061 | C62: Expense | D62: Travel | E62: Bus and auto fare | F62: 80 | G62: UPI | H62: =TEXT(A62,"mmm-yyyy") -> Mar-2026 | I62: =SUMIFS($F$2:F171,$C$2:C171,"Income")-SUMIFS($F$2:F171,$C$2:C171,"Expense") -> 1735 | J62: =IF(C62="Income","-",IFERROR(VLOOKUP(D62,Budget!$A$2:$F$12,6,FALSE),"-")) -> Within Budget
A63: 46093 | B63: TX062 | C63: Expense | D63: Food | E63: College canteen lunch | F63: 130 | G63: UPI | H63: =TEXT(A63,"mmm-yyyy") -> Mar-2026 | I63: =SUMIFS($F$2:F171,$C$2:C171,"Income")-SUMIFS($F$2:F171,$C$2:C171,"Expense") -> 1735 | J63: =IF(C63="Income","-",IFERROR(VLOOKUP(D63,Budget!$A$2:$F$12,6,FALSE),"-")) -> Within Budget
A64: 46094 | B64: TX063 | C64: Expense | D64: Stationery | E64: Highlighters and sticky notes | F64: 110 | G64: Cash | H64: =TEXT(A64,"mmm-yyyy") -> Mar-2026 | I64: =SUMIFS($F$2:F171,$C$2:C171,"Income")-SUMIFS($F$2:F171,$C$2:C171,"Expense") -> 1735 | J64: =IF(C64="Income","-",IFERROR(VLOOKUP(D64,Budget!$A$2:$F$12,6,FALSE),"-")) -> Within Budget
A65: 46095 | B65: TX064 | C65: Expense | D65: Food | E65: Evening snacks with friends | F65: 95 | G65: Cash | H65: =TEXT(A65,"mmm-yyyy") -> Mar-2026 | I65: =SUMIFS($F$2:F171,$C$2:C171,"Income")-SUMIFS($F$2:F171,$C$2:C171,"Expense") -> 1735 | J65: =IF(C65="Income","-",IFERROR(VLOOKUP(D65,Budget!$A$2:$F$12,6,FALSE),"-")) -> Within Budget
A66: 46096 | B66: TX065 | C66: Income | D66: Pocket Money | E66: Mid-month allowance bonus | F66: 500 | G66: UPI | H66: =TEXT(A66,"mmm-yyyy") -> Mar-2026 | I66: =SUMIFS($F$2:F171,$C$2:C171,"Income")-SUMIFS($F$2:F171,$C$2:C171,"Expense") -> 1735 | J66: =IF(C66="Income","-",IFERROR(VLOOKUP(D66,Budget!$A$2:$F$12,6,FALSE),"-")) -> -
A67: 46097 | B67: TX066 | C67: Expense | D67: Travel | E67: Bus fare | F67: 40 | G67: Cash | H67: =TEXT(A67,"mmm-yyyy") -> Mar-2026 | I67: =SUMIFS($F$2:F171,$C$2:C171,"Income")-SUMIFS($F$2:F171,$C$2:C171,"Expense") -> 1735 | J67: =IF(C67="Income","-",IFERROR(VLOOKUP(D67,Budget!$A$2:$F$12,6,FALSE),"-")) -> Within Budget
A68: 46098 | B68: TX067 | C68: Expense | D68: Food | E68: Lunch at cafe | F68: 160 | G68: UPI | H68: =TEXT(A68,"mmm-yyyy") -> Mar-2026 | I68: =SUMIFS($F$2:F171,$C$2:C171,"Income")-SUMIFS($F$2:F171,$C$2:C171,"Expense") -> 1735 | J68: =IF(C68="Income","-",IFERROR(VLOOKUP(D68,Budget!$A$2:$F$12,6,FALSE),"-")) -> Within Budget
A69: 46099 | B69: TX068 | C69: Expense | D69: Education | E69: Sem exam photocopying & bind | F69: 120 | G69: Cash | H69: =TEXT(A69,"mmm-yyyy") -> Mar-2026 | I69: =SUMIFS($F$2:F171,$C$2:C171,"Income")-SUMIFS($F$2:F171,$C$2:C171,"Expense") -> 1735 | J69: =IF(C69="Income","-",IFERROR(VLOOKUP(D69,Budget!$A$2:$F$12,6,FALSE),"-")) -> Within Budget
A70: 46100 | B70: TX069 | C70: Expense | D70: Personal Care | E70: Skincare & toiletries | F70: 190 | G70: UPI | H70: =TEXT(A70,"mmm-yyyy") -> Mar-2026 | I70: =SUMIFS($F$2:F171,$C$2:C171,"Income")-SUMIFS($F$2:F171,$C$2:C171,"Expense") -> 1735 | J70: =IF(C70="Income","-",IFERROR(VLOOKUP(D70,Budget!$A$2:$F$12,6,FALSE),"-")) -> Within Budget
A71: 46101 | B71: TX070 | C71: Expense | D71: Food | E71: Pizza treat with friends | F71: 310 | G71: UPI | H71: =TEXT(A71,"mmm-yyyy") -> Mar-2026 | I71: =SUMIFS($F$2:F171,$C$2:C171,"Income")-SUMIFS($F$2:F171,$C$2:C171,"Expense") -> 1735 | J71: =IF(C71="Income","-",IFERROR(VLOOKUP(D71,Budget!$A$2:$F$12,6,FALSE),"-")) -> Within Budget
A72: 46102 | B72: TX071 | C72: Expense | D72: Travel | E72: Metro and rickshaw | F72: 70 | G72: UPI | H72: =TEXT(A72,"mmm-yyyy") -> Mar-2026 | I72: =SUMIFS($F$2:F171,$C$2:C171,"Income")-SUMIFS($F$2:F171,$C$2:C171,"Expense") -> 1735 | J72: =IF(C72="Income","-",IFERROR(VLOOKUP(D72,Budget!$A$2:$F$12,6,FALSE),"-")) -> Within Budget
A73: 46103 | B73: TX072 | C73: Expense | D73: Shopping | E73: Book and stationery holder | F73: 250 | G73: UPI | H73: =TEXT(A73,"mmm-yyyy") -> Mar-2026 | I73: =SUMIFS($F$2:F171,$C$2:C171,"Income")-SUMIFS($F$2:F171,$C$2:C171,"Expense") -> 1735 | J73: =IF(C73="Income","-",IFERROR(VLOOKUP(D73,Budget!$A$2:$F$12,6,FALSE),"-")) -> Within Budget
A74: 46104 | B74: TX073 | C74: Expense | D74: Food | E74: Breakfast and juice | F74: 85 | G74: Cash | H74: =TEXT(A74,"mmm-yyyy") -> Mar-2026 | I74: =SUMIFS($F$2:F171,$C$2:C171,"Income")-SUMIFS($F$2:F171,$C$2:C171,"Expense") -> 1735 | J74: =IF(C74="Income","-",IFERROR(VLOOKUP(D74,Budget!$A$2:$F$12,6,FALSE),"-")) -> Within Budget
A75: 46105 | B75: TX074 | C75: Expense | D75: Entertainment | E75: Movie ticket (weekend) | F75: 220 | G75: UPI | H75: =TEXT(A75,"mmm-yyyy") -> Mar-2026 | I75: =SUMIFS($F$2:F171,$C$2:C171,"Income")-SUMIFS($F$2:F171,$C$2:C171,"Expense") -> 1735 | J75: =IF(C75="Income","-",IFERROR(VLOOKUP(D75,Budget!$A$2:$F$12,6,FALSE),"-")) -> Near Limit
A76: 46106 | B76: TX075 | C76: Income | D76: Savings Interest | E76: Quarterly bank interest | F76: 42 | G76: Bank | H76: =TEXT(A76,"mmm-yyyy") -> Mar-2026 | I76: =SUMIFS($F$2:F171,$C$2:C171,"Income")-SUMIFS($F$2:F171,$C$2:C171,"Expense") -> 1735 | J76: =IF(C76="Income","-",IFERROR(VLOOKUP(D76,Budget!$A$2:$F$12,6,FALSE),"-")) -> -
A77: 46107 | B77: TX076 | C77: Expense | D77: Travel | E77: Bus fare | F77: 40 | G77: Cash | H77: =TEXT(A77,"mmm-yyyy") -> Mar-2026 | I77: =SUMIFS($F$2:F171,$C$2:C171,"Income")-SUMIFS($F$2:F171,$C$2:C171,"Expense") -> 1735 | J77: =IF(C77="Income","-",IFERROR(VLOOKUP(D77,Budget!$A$2:$F$12,6,FALSE),"-")) -> Within Budget
A78: 46108 | B78: TX077 | C78: Expense | D78: Health | E78: First aid & pain relief meds | F78: 140 | G78: UPI | H78: =TEXT(A78,"mmm-yyyy") -> Mar-2026 | I78: =SUMIFS($F$2:F171,$C$2:C171,"Income")-SUMIFS($F$2:F171,$C$2:C171,"Expense") -> 1735 | J78: =IF(C78="Income","-",IFERROR(VLOOKUP(D78,Budget!$A$2:$F$12,6,FALSE),"-")) -> Within Budget
A79: 46109 | B79: TX078 | C79: Expense | D79: Food | E79: Dinner with roommates | F79: 180 | G79: UPI | H79: =TEXT(A79,"mmm-yyyy") -> Mar-2026 | I79: =SUMIFS($F$2:F171,$C$2:C171,"Income")-SUMIFS($F$2:F171,$C$2:C171,"Expense") -> 1735 | J79: =IF(C79="Income","-",IFERROR(VLOOKUP(D79,Budget!$A$2:$F$12,6,FALSE),"-")) -> Within Budget
A80: 46110 | B80: TX079 | C80: Expense | D80: Gifts | E80: Friend's birthday gift | F80: 250 | G80: UPI | H80: =TEXT(A80,"mmm-yyyy") -> Mar-2026 | I80: =SUMIFS($F$2:F171,$C$2:C171,"Income")-SUMIFS($F$2:F171,$C$2:C171,"Expense") -> 1735 | J80: =IF(C80="Income","-",IFERROR(VLOOKUP(D80,Budget!$A$2:$F$12,6,FALSE),"-")) -> Within Budget
A81: 46111 | B81: TX080 | C81: Expense | D81: Other | E81: Laundry & dry cleaning | F81: 160 | G81: Cash | H81: =TEXT(A81,"mmm-yyyy") -> Mar-2026 | I81: =SUMIFS($F$2:F171,$C$2:C171,"Income")-SUMIFS($F$2:F171,$C$2:C171,"Expense") -> 1735 | J81: =IF(C81="Income","-",IFERROR(VLOOKUP(D81,Budget!$A$2:$F$12,6,FALSE),"-")) -> Within Budget
A82: 46113 | B82: TX081 | C82: Income | D82: Pocket Money | E82: April monthly allowance | F82: 3200 | G82: UPI | H82: =TEXT(A82,"mmm-yyyy") -> Apr-2026 | I82: =SUMIFS($F$2:F171,$C$2:C171,"Income")-SUMIFS($F$2:F171,$C$2:C171,"Expense") -> 1735 | J82: =IF(C82="Income","-",IFERROR(VLOOKUP(D82,Budget!$A$2:$F$12,6,FALSE),"-")) -> -
A83: 46114 | B83: TX082 | C83: Expense | D83: Food | E83: Breakfast and coffee | F83: 75 | G83: UPI | H83: =TEXT(A83,"mmm-yyyy") -> Apr-2026 | I83: =SUMIFS($F$2:F171,$C$2:C171,"Income")-SUMIFS($F$2:F171,$C$2:C171,"Expense") -> 1735 | J83: =IF(C83="Income","-",IFERROR(VLOOKUP(D83,Budget!$A$2:$F$12,6,FALSE),"-")) -> Within Budget
A84: 46115 | B84: TX083 | C84: Expense | D84: Travel | E84: Monthly bus pass recharge | F84: 450 | G84: UPI | H84: =TEXT(A84,"mmm-yyyy") -> Apr-2026 | I84: =SUMIFS($F$2:F171,$C$2:C171,"Income")-SUMIFS($F$2:F171,$C$2:C171,"Expense") -> 1735 | J84: =IF(C84="Income","-",IFERROR(VLOOKUP(D84,Budget!$A$2:$F$12,6,FALSE),"-")) -> Within Budget
A85: 46116 | B85: TX084 | C85: Expense | D85: Food | E85: College lunch | F85: 120 | G85: UPI | H85: =TEXT(A85,"mmm-yyyy") -> Apr-2026 | I85: =SUMIFS($F$2:F171,$C$2:C171,"Income")-SUMIFS($F$2:F171,$C$2:C171,"Expense") -> 1735 | J85: =IF(C85="Income","-",IFERROR(VLOOKUP(D85,Budget!$A$2:$F$12,6,FALSE),"-")) -> Within Budget
A86: 46117 | B86: TX085 | C86: Expense | D86: Stationery | E86: Exam answer sheets & pens | F86: 150 | G86: Cash | H86: =TEXT(A86,"mmm-yyyy") -> Apr-2026 | I86: =SUMIFS($F$2:F171,$C$2:C171,"Income")-SUMIFS($F$2:F171,$C$2:C171,"Expense") -> 1735 | J86: =IF(C86="Income","-",IFERROR(VLOOKUP(D86,Budget!$A$2:$F$12,6,FALSE),"-")) -> Within Budget
...

Sheet Budget
A1: Category | B1: Monthly Budget | C1: Actual Spending | D1: Remaining Budget | E1: Budget Usage (%) | F1: Status
A2: Food | B2: 1800 | C2: =SUMIFS(Transactions!$F:$F,Transactions!$D:$D,$A2,Transactions!$C:$C,"Expense",Transactions!$A:$A,">="&Dashboard!$B$2,Transactions!$A:$A,"<"&EDATE(Dashboard!$B$2,1)) -> 1285 | D2: =B2-C2 -> 515 | E2: =IFERROR(C2/B2,0) -> 0.71388889 | F2: =IF(C2>B2,"Over Budget",IF(C2>=B2*0.8,"Near Limit","Within Budget")) -> Within Budget
A3: Travel | B3: 800 | C3: =SUMIFS(Transactions!$F:$F,Transactions!$D:$D,$A3,Transactions!$C:$C,"Expense",Transactions!$A:$A,">="&Dashboard!$B$2,Transactions!$A:$A,"<"&EDATE(Dashboard!$B$2,1)) -> 390 | D3: =B3-C3 -> 410 | E3: =IFERROR(C3/B3,0) -> 0.4875 | F3: =IF(C3>B3,"Over Budget",IF(C3>=B3*0.8,"Near Limit","Within Budget")) -> Within Budget
A4: Stationery | B4: 500 | C4: =SUMIFS(Transactions!$F:$F,Transactions!$D:$D,$A4,Transactions!$C:$C,"Expense",Transactions!$A:$A,">="&Dashboard!$B$2,Transactions!$A:$A,"<"&EDATE(Dashboard!$B$2,1)) -> 180 | D4: =B4-C4 -> 320 | E4: =IFERROR(C4/B4,0) -> 0.36 | F4: =IF(C4>B4,"Over Budget",IF(C4>=B4*0.8,"Near Limit","Within Budget")) -> Within Budget
A5: Education | B5: 600 | C5: =SUMIFS(Transactions!$F:$F,Transactions!$D:$D,$A5,Transactions!$C:$C,"Expense",Transactions!$A:$A,">="&Dashboard!$B$2,Transactions!$A:$A,"<"&EDATE(Dashboard!$B$2,1)) -> 255 | D5: =B5-C5 -> 345 | E5: =IFERROR(C5/B5,0) -> 0.425 | F5: =IF(C5>B5,"Over Budget",IF(C5>=B5*0.8,"Near Limit","Within Budget")) -> Within Budget
A6: Entertainment | B6: 700 | C6: =SUMIFS(Transactions!$F:$F,Transactions!$D:$D,$A6,Transactions!$C:$C,"Expense",Transactions!$A:$A,">="&Dashboard!$B$2,Transactions!$A:$A,"<"&EDATE(Dashboard!$B$2,1)) -> 568 | D6: =B6-C6 -> 132 | E6: =IFERROR(C6/B6,0) -> 0.81142857 | F6: =IF(C6>B6,"Over Budget",IF(C6>=B6*0.8,"Near Limit","Within Budget")) -> Near Limit
A7: Mobile | B7: 300 | C7: =SUMIFS(Transactions!$F:$F,Transactions!$D:$D,$A7,Transactions!$C:$C,"Expense",Transactions!$A:$A,">="&Dashboard!$B$2,Transactions!$A:$A,"<"&EDATE(Dashboard!$B$2,1)) -> 239 | D7: =B7-C7 -> 61 | E7: =IFERROR(C7/B7,0) -> 0.79666667 | F7: =IF(C7>B7,"Over Budget",IF(C7>=B7*0.8,"Near Limit","Within Budget")) -> Within Budget
A8: Shopping | B8: 1000 | C8: =SUMIFS(Transactions!$F:$F,Transactions!$D:$D,$A8,Transactions!$C:$C,"Expense",Transactions!$A:$A,">="&Dashboard!$B$2,Transactions!$A:$A,"<"&EDATE(Dashboard!$B$2,1)) -> 750 | D8: =B8-C8 -> 250 | E8: =IFERROR(C8/B8,0) -> 0.75 | F8: =IF(C8>B8,"Over Budget",IF(C8>=B8*0.8,"Near Limit","Within Budget")) -> Within Budget
A9: Personal Care | B9: 400 | C9: =SUMIFS(Transactions!$F:$F,Transactions!$D:$D,$A9,Transactions!$C:$C,"Expense",Transactions!$A:$A,">="&Dashboard!$B$2,Transactions!$A:$A,"<"&EDATE(Dashboard!$B$2,1)) -> 220 | D9: =B9-C9 -> 180 | E9: =IFERROR(C9/B9,0) -> 0.55 | F9: =IF(C9>B9,"Over Budget",IF(C9>=B9*0.8,"Near Limit","Within Budget")) -> Within Budget
A10: Health | B10: 300 | C10: =SUMIFS(Transactions!$F:$F,Transactions!$D:$D,$A10,Transactions!$C:$C,"Expense",Transactions!$A:$A,">="&Dashboard!$B$2,Transactions!$A:$A,"<"&EDATE(Dashboard!$B$2,1)) -> 0 | D10: =B10-C10 -> 300 | E10: =IFERROR(C10/B10,0) -> 0 | F10: =IF(C10>B10,"Over Budget",IF(C10>=B10*0.8,"Near Limit","Within Budget")) -> Within Budget
A11: Gifts | B11: 300 | C11: =SUMIFS(Transactions!$F:$F,Transactions!$D:$D,$A11,Transactions!$C:$C,"Expense",Transactions!$A:$A,">="&Dashboard!$B$2,Transactions!$A:$A,"<"&EDATE(Dashboard!$B$2,1)) -> 0 | D11: =B11-C11 -> 300 | E11: =IFERROR(C11/B11,0) -> 0 | F11: =IF(C11>B11,"Over Budget",IF(C11>=B11*0.8,"Near Limit","Within Budget")) -> Within Budget
A12: Other | B12: 300 | C12: =SUMIFS(Transactions!$F:$F,Transactions!$D:$D,$A12,Transactions!$C:$C,"Expense",Transactions!$A:$A,">="&Dashboard!$B$2,Transactions!$A:$A,"<"&EDATE(Dashboard!$B$2,1)) -> 0 | D12: =B12-C12 -> 300 | E12: =IFERROR(C12/B12,0) -> 0 | F12: =IF(C12>B12,"Over Budget",IF(C12>=B12*0.8,"Near Limit","Within Budget")) -> Within Budget
A13: Total | B13: =SUM(B2:B12) -> 7000 | C13: =SUM(C2:C12) -> 3887 | D13: =B13-C13 -> 3113 | E13: =IFERROR(C13/B13,0) -> 0.55528571 | F13: =IF(C13>B13,"Over Budget",IF(C13>=B13*0.8,"Near Limit","Within Budget")) -> Within Budget

Sheet Monthly Summary
A1: Month | B1: Total Income | C1: Total Expenses | D1: Net Savings | E1: Savings Rate | F1: Transaction Count | G1: Expense Change
A2: 46023 | B2: =SUMIFS(Transactions!$F:$F,Transactions!$C:$C,"Income",Transactions!$A:$A,">="&$A2,Transactions!$A:$A,"<"&EDATE($A2,1)) -> 4035 | C2: =SUMIFS(Transactions!$F:$F,Transactions!$C:$C,"Expense",Transactions!$A:$A,">="&$A2,Transactions!$A:$A,"<"&EDATE($A2,1)) -> 3887 | D2: =B2-C2 -> 148 | E2: =IFERROR(D2/B2,0) -> 0.036679058 | F2: =COUNTIFS(Transactions!$A:$A,">="&$A2,Transactions!$A:$A,"<"&EDATE($A2,1)) -> 30 | G2: 0
A3: =EDATE(A2,1) -> 46054 | B3: =SUMIFS(Transactions!$F:$F,Transactions!$C:$C,"Income",Transactions!$A:$A,">="&$A3,Transactions!$A:$A,"<"&EDATE($A3,1)) -> 4000 | C3: =SUMIFS(Transactions!$F:$F,Transactions!$C:$C,"Expense",Transactions!$A:$A,">="&$A3,Transactions!$A:$A,"<"&EDATE($A3,1)) -> 3489 | D3: =B3-C3 -> 511 | E3: =IFERROR(D3/B3,0) -> 0.12775 | F3: =COUNTIFS(Transactions!$A:$A,">="&$A3,Transactions!$A:$A,"<"&EDATE($A3,1)) -> 20 | G3: =IF(OR(C3=0,C2=0),0,IFERROR((C3-C2)/C2,0)) -> -0.10239259
A4: =EDATE(A3,1) -> 46082 | B4: =SUMIFS(Transactions!$F:$F,Transactions!$C:$C,"Income",Transactions!$A:$A,">="&$A4,Transactions!$A:$A,"<"&EDATE($A4,1)) -> 4342 | C4: =SUMIFS(Transactions!$F:$F,Transactions!$C:$C,"Expense",Transactions!$A:$A,">="&$A4,Transactions!$A:$A,"<"&EDATE($A4,1)) -> 4253 | D4: =B4-C4 -> 89 | E4: =IFERROR(D4/B4,0) -> 0.020497467 | F4: =COUNTIFS(Transactions!$A:$A,">="&$A4,Transactions!$A:$A,"<"&EDATE($A4,1)) -> 30 | G4: =IF(OR(C4=0,C3=0),0,IFERROR((C4-C3)/C3,0)) -> 0.21897392
A5: =EDATE(A4,1) -> 46113 | B5: =SUMIFS(Transactions!$F:$F,Transactions!$C:$C,"Income",Transactions!$A:$A,">="&$A5,Transactions!$A:$A,"<"&EDATE($A5,1)) -> 5000 | C5: =SUMIFS(Transactions!$F:$F,Transactions!$C:$C,"Expense",Transactions!$A:$A,">="&$A5,Transactions!$A:$A,"<"&EDATE($A5,1)) -> 4570 | D5: =B5-C5 -> 430 | E5: =IFERROR(D5/B5,0) -> 0.086 | F5: =COUNTIFS(Transactions!$A:$A,">="&$A5,Transactions!$A:$A,"<"&EDATE($A5,1)) -> 30 | G5: =IF(OR(C5=0,C4=0),0,IFERROR((C5-C4)/C4,0)) -> 0.074535622
A6: =EDATE(A5,1) -> 46143 | B6: =SUMIFS(Transactions!$F:$F,Transactions!$C:$C,"Income",Transactions!$A:$A,">="&$A6,Transactions!$A:$A,"<"&EDATE($A6,1)) -> 5238 | C6: =SUMIFS(Transactions!$F:$F,Transactions!$C:$C,"Expense",Transactions!$A:$A,">="&$A6,Transactions!$A:$A,"<"&EDATE($A6,1)) -> 5524 | D6: =B6-C6 -> -286 | E6: =IFERROR(D6/B6,0) -> -0.054600993 | F6: =COUNTIFS(Transactions!$A:$A,">="&$A6,Transactions!$A:$A,"<"&EDATE($A6,1)) -> 30 | G6: =IF(OR(C6=0,C5=0),0,IFERROR((C6-C5)/C5,0)) -> 0.20875274
A7: =EDATE(A6,1) -> 46174 | B7: =SUMIFS(Transactions!$F:$F,Transactions!$C:$C,"Income",Transactions!$A:$A,">="&$A7,Transactions!$A:$A,"<"&EDATE($A7,1)) -> 6045 | C7: =SUMIFS(Transactions!$F:$F,Transactions!$C:$C,"Expense",Transactions!$A:$A,">="&$A7,Transactions!$A:$A,"<"&EDATE($A7,1)) -> 5202 | D7: =B7-C7 -> 843 | E7: =IFERROR(D7/B7,0) -> 0.13945409 | F7: =COUNTIFS(Transactions!$A:$A,">="&$A7,Transactions!$A:$A,"<"&EDATE($A7,1)) -> 30 | G7: =IF(OR(C7=0,C6=0),0,IFERROR((C7-C6)/C6,0)) -> -0.058291093
A8: =EDATE(A7,1) -> 46204 | B8: =SUMIFS(Transactions!$F:$F,Transactions!$C:$C,"Income",Transactions!$A:$A,">="&$A8,Transactions!$A:$A,"<"&EDATE($A8,1)) -> 0 | C8: =SUMIFS(Transactions!$F:$F,Transactions!$C:$C,"Expense",Transactions!$A:$A,">="&$A8,Transactions!$A:$A,"<"&EDATE($A8,1)) -> 0 | D8: =B8-C8 -> 0 | E8: =IFERROR(D8/B8,0) -> 0 | F8: =COUNTIFS(Transactions!$A:$A,">="&$A8,Transactions!$A:$A,"<"&EDATE($A8,1)) -> 0 | G8: =IF(OR(C8=0,C7=0),0,IFERROR((C8-C7)/C7,0)) -> 0
A9: =EDATE(A8,1) -> 46235 | B9: =SUMIFS(Transactions!$F:$F,Transactions!$C:$C,"Income",Transactions!$A:$A,">="&$A9,Transactions!$A:$A,"<"&EDATE($A9,1)) -> 0 | C9: =SUMIFS(Transactions!$F:$F,Transactions!$C:$C,"Expense",Transactions!$A:$A,">="&$A9,Transactions!$A:$A,"<"&EDATE($A9,1)) -> 0 | D9: =B9-C9 -> 0 | E9: =IFERROR(D9/B9,0) -> 0 | F9: =COUNTIFS(Transactions!$A:$A,">="&$A9,Transactions!$A:$A,"<"&EDATE($A9,1)) -> 0 | G9: =IF(OR(C9=0,C8=0),0,IFERROR((C9-C8)/C8,0)) -> 0
A10: =EDATE(A9,1) -> 46266 | B10: =SUMIFS(Transactions!$F:$F,Transactions!$C:$C,"Income",Transactions!$A:$A,">="&$A10,Transactions!$A:$A,"<"&EDATE($A10,1)) -> 0 | C10: =SUMIFS(Transactions!$F:$F,Transactions!$C:$C,"Expense",Transactions!$A:$A,">="&$A10,Transactions!$A:$A,"<"&EDATE($A10,1)) -> 0 | D10: =B10-C10 -> 0 | E10: =IFERROR(D10/B10,0) -> 0 | F10: =COUNTIFS(Transactions!$A:$A,">="&$A10,Transactions!$A:$A,"<"&EDATE($A10,1)) -> 0 | G10: =IF(OR(C10=0,C9=0),0,IFERROR((C10-C9)/C9,0)) -> 0
A11: =EDATE(A10,1) -> 46296 | B11: =SUMIFS(Transactions!$F:$F,Transactions!$C:$C,"Income",Transactions!$A:$A,">="&$A11,Transactions!$A:$A,"<"&EDATE($A11,1)) -> 0 | C11: =SUMIFS(Transactions!$F:$F,Transactions!$C:$C,"Expense",Transactions!$A:$A,">="&$A11,Transactions!$A:$A,"<"&EDATE($A11,1)) -> 0 | D11: =B11-C11 -> 0 | E11: =IFERROR(D11/B11,0) -> 0 | F11: =COUNTIFS(Transactions!$A:$A,">="&$A11,Transactions!$A:$A,"<"&EDATE($A11,1)) -> 0 | G11: =IF(OR(C11=0,C10=0),0,IFERROR((C11-C10)/C10,0)) -> 0
A12: =EDATE(A11,1) -> 46327 | B12: =SUMIFS(Transactions!$F:$F,Transactions!$C:$C,"Income",Transactions!$A:$A,">="&$A12,Transactions!$A:$A,"<"&EDATE($A12,1)) -> 0 | C12: =SUMIFS(Transactions!$F:$F,Transactions!$C:$C,"Expense",Transactions!$A:$A,">="&$A12,Transactions!$A:$A,"<"&EDATE($A12,1)) -> 0 | D12: =B12-C12 -> 0 | E12: =IFERROR(D12/B12,0) -> 0 | F12: =COUNTIFS(Transactions!$A:$A,">="&$A12,Transactions!$A:$A,"<"&EDATE($A12,1)) -> 0 | G12: =IF(OR(C12=0,C11=0),0,IFERROR((C12-C11)/C11,0)) -> 0
A13: =EDATE(A12,1) -> 46357 | B13: =SUMIFS(Transactions!$F:$F,Transactions!$C:$C,"Income",Transactions!$A:$A,">="&$A13,Transactions!$A:$A,"<"&EDATE($A13,1)) -> 0 | C13: =SUMIFS(Transactions!$F:$F,Transactions!$C:$C,"Expense",Transactions!$A:$A,">="&$A13,Transactions!$A:$A,"<"&EDATE($A13,1)) -> 0 | D13: =B13-C13 -> 0 | E13: =IFERROR(D13/B13,0) -> 0 | F13: =COUNTIFS(Transactions!$A:$A,">="&$A13,Transactions!$A:$A,"<"&EDATE($A13,1)) -> 0 | G13: =IF(OR(C13=0,C12=0),0,IFERROR((C13-C12)/C12,0)) -> 0
A14: Total / Average | B14: =SUM(B2:B13) -> 28660 | C14: =SUM(C2:C13) -> 26925 | D14: =SUM(D2:D13) -> 1735 | E14: =IFERROR(D14/B14,0) -> 0.060537334 | F14: =SUM(F2:F13) -> 170 | G14: -

Sheet Savings Goals
A1: POCKET MONEY SAVINGS GOALS TRACKER
B3: TOTAL TARGET | D3: TOTAL SAVED | F3: OVERALL PROGRESS | H3: REMAINING AMOUNT
B4: =SUM(D7:D11) -> 17000 | D4: =SUM(E7:E11) -> 10300 | F4: =IFERROR(D4/B4,0) -> 0.60588235 | H4: =B4-D4 -> 6700
A6: Goal ID | B6: Goal Name | C6: Category | D6: Target Amount | E6: Current Saved | F6: Monthly Target | G6: Target Date | H6: Progress (%) | I6: Remaining | J6: Status
A7: SG01 | B7: Emergency Fund (3 Months) | C7: Financial Safety | D7: 5000 | E7: 3500 | F7: 500 | G7: 46203 | H7: =E7/D7 -> 0.7 | I7: =D7-E7 -> 1500 | J7: =IF(H7>=1,"Achieved",IF(H7>=0.7,"On Track",IF(H7>=0.4,"In Progress","Needs Attention"))) -> On Track
A8: SG02 | B8: Noise-Cancelling Headphones | C8: Tech & Gadgets | D8: 3500 | E8: 2800 | F8: 700 | G8: 46127 | H8: =E8/D8 -> 0.8 | I8: =D8-E8 -> 700 | J8: =IF(H8>=1,"Achieved",IF(H8>=0.7,"On Track",IF(H8>=0.4,"In Progress","Needs Attention"))) -> On Track
A9: SG03 | B9: College Tech Fest Trip | C9: Travel & Events | D9: 4000 | E9: 1600 | F9: 800 | G9: 46162 | H9: =E9/D9 -> 0.4 | I9: =D9-E9 -> 2400 | J9: =IF(H9>=1,"Achieved",IF(H9>=0.7,"On Track",IF(H9>=0.4,"In Progress","Needs Attention"))) -> In Progress
A10: SG04 | B10: Data Science & AI Course | C10: Skill Building | D10: 2500 | E10: 1000 | F10: 300 | G10: 46265 | H10: =E10/D10 -> 0.4 | I10: =D10-E10 -> 1500 | J10: =IF(H10>=1,"Achieved",IF(H10>=0.7,"On Track",IF(H10>=0.4,"In Progress","Needs Attention"))) -> In Progress
A11: SG05 | B11: Mom's Birthday Gift | C11: Family & Gifts | D11: 2000 | E11: 1400 | F11: 300 | G11: 46213 | H11: =E11/D11 -> 0.7 | I11: =D11-E11 -> 600 | J11: =IF(H11>=1,"Achieved",IF(H11>=0.7,"On Track",IF(H11>=0.4,"In Progress","Needs Attention"))) -> On Track
B12: Total | D12: =SUM(D7:D11) -> 17000 | E12: =SUM(E7:E11) -> 10300 | F12: =SUM(F7:F11) -> 2600 | H12: =IFERROR(E12/D12,0) -> 0.60588235 | I12: =SUM(I7:I11) -> 6700

Sheet Categories
A1: Category | B1: Type
A2: Pocket Money | B2: Income
A3: Gift | B3: Income
A4: Part-time Work | B4: Income
A5: Savings Interest | B5: Income
A6: Food | B6: Expense
A7: Travel | B7: Expense
A8: Stationery | B8: Expense
A9: Education | B9: Expense
A10: Entertainment | B10: Expense
A11: Mobile | B11: Expense
A12: Shopping | B12: Expense
... A16: Other | B16: Expense
